Workbook

Sheet Test Cases
A1: Test Case ID | B1: Module | C1: Test Scenario | D1: Priority | E1: Type | F1: Preconditions | G1: Test Steps | H1: Test Data | I1: Expected Result | J1: Status | K1: Notes / Actual Result
A2: AUTH-001 | B2: Authentication & Accounts | C2: Sign up with valid email & password | D2: High | E2: Functional | F2: User not registered; on Sign Up page | G2: 1. Go to Sign Up 2. Enter first name, last name, email, password 3. Tap Sign Up | H2: Email: newuser@test.com / Password: Test@1234 | I2: Account created; verification email sent; success/confirmation screen shown | J2: Run
A3: AUTH-002 | B3: Authentication & Accounts | C3: Sign up with already-registered email | D3: High | E3: Negative | F3: An account already exists for the email | G3: 1. Go to Sign Up 2. Enter an email already in use 3. Submit | H3: Existing email: driver1@test.com | I3: Error 'Email already registered'; no new account created | J3: Run
A4: AUTH-003 | B4: Authentication & Accounts | C4: Sign up with invalid email format | D4: Medium | E4: Negative | F4: On Sign Up page | G4: 1. Enter malformed email 2. Submit | H4: user@@test, userattest.com | I4: Inline validation error; form does not submit | J4: Run
A5: AUTH-004 | B5: Authentication & Accounts | C5: Sign up with weak/short password | D5: Medium | E5: Negative | F5: On Sign Up page | G5: 1. Enter password below minimum strength/length 2. Submit | H5: Password: 123 | I5: Password strength error shown; account not created | J5: Run
A6: AUTH-005 | B6: Authentication & Accounts | C6: Sign up with required fields blank | D6: Medium | E6: Negative | F6: On Sign Up page | G6: 1. Leave first name / last name blank 2. Submit | H6: First name: (blank) | I6: Field-level 'required' errors shown; form does not submit | J6: Run
A7: AUTH-006 | B7: Authentication & Accounts | C7: Sign up via Google OAuth (new user) | D7: High | E7: Functional | F7: User not registered; Google account available | G7: 1. Tap 'Continue with Google' 2. Complete Google consent 3. Return to app | H7: Valid Google test account | I7: Account auto-created from Google profile; user logged in / routed to profile completion | J7: Run
A8: AUTH-007 | B8: Authentication & Accounts | C8: Google OAuth with email that already has a password account | D8: Medium | E8: Edge Case | F8: Email/password account already exists for that email | G8: 1. Sign up via Google using an email already registered via password 2. Observe result | H8: Existing email used for Google login | I8: System either links accounts or shows a clear conflict message (no silent duplicate account created) | J8: Run
A9: AUTH-008 | B9: Authentication & Accounts | C9: Email verification link - valid & unused | D9: High | E9: Functional | F9: Signup completed, verification email received | G9: 1. Open verification email 2. Click verification link | H9: - | I9: Account marked verified; user can now log in | J9: Run
A10: AUTH-009 | B10: Authentication & Accounts | C10: Email verification link - expired | D10: Medium | E10: Negative | F10: Verification link older than expiry window | G10: 1. Click expired verification link | H10: - | I10: Error shown; option to resend verification email is offered | J10: Run
A11: AUTH-010 | B11: Authentication & Accounts | C11: Email verification link used twice | D11: Low | E11: Edge Case | F11: Link already used once | G11: 1. Click the same verification link again | H11: - | I11: Appropriate 'already verified' message; no error/duplicate action | J11: Run
A12: AUTH-011 | B12: Authentication & Accounts | C12: Login attempt before email verification | D12: High | E12: Negative | F12: Account created but not yet verified | G12: 1. Attempt to log in with unverified account | H12: Valid credentials, unverified account | I12: Login blocked or restricted with a clear 'please verify your email' message | J12: Run
A13: AUTH-012 | B13: Authentication & Accounts | C13: Login with valid verified credentials | D13: High | E13: Functional | F13: Verified account exists | G13: 1. Enter correct email/password 2. Submit | H13: Valid verified account | I13: Login succeeds; user routed to home/dashboard | J13: Run
... A35: PROF-006 | B35: User Profiles | C35: Upload oversized profile photo | D35: Low | E35: Negative | F35: User logged in, on Edit Profile | G35: 1. Attempt to upload an image exceeding the max file size | H35: 20MB image | I35: Upload rejected with a file-size error | J35: Run
A36: PROF-007 | B36: User Profiles | C36: Age range field left blank | D36: Low | E36: Edge Case | F36: User logged in, on Edit Profile | G36: 1. Leave age range unselected 2. Save | H36: - | I36: Profile saves successfully; age range omitted from public profile | J36: Not Run | K36: No age option in edit profile
A37: PROF-008 | B37: User Profiles | C37: Private fields hidden on other users' public profiles | D37: High | E37: Security | F37: Two accounts exist | G37: 1. View another user's public profile | H37: - | I37: Email, phone number, and payment details are NOT visible | J37: Not Run
A38: PROF-009 | B38: User Profiles | C38: Own private fields visible to self | D38: Medium | E38: Functional | F38: User logged in | G38: 1. View own account/profile settings | H38: - | I38: Email, phone, and payment details visible to the account owner | J38: Run
A39: PROF-010 | B39: User Profiles | C39: Rating (stars + count) displays accurately | D39: Medium | E39: Functional | F39: User has received multiple ratings | G39: 1. View profile after several completed, rated trips | H39: e.g. 3 ratings: 5,4,5 | I39: Average stars and total rating count match underlying data (e.g. 4.7, 3 ratings) | J39: Run
A40: PROF-011 | B40: User Profiles | C40: 'Trips completed' counter accuracy | D40: Medium | E40: Functional | F40: User has completed at least one trip | G40: 1. Complete a trip 2. View profile | H40: - | I40: Counter increments by exactly 1 per completed trip | J40: Run
A41: PROF-012 | B41: User Profiles | C41: New user profile shows zero-state correctly | D41: Low | E41: Edge Case | F41: Newly created account with no trips/ratings | G41: 1. View own profile immediately after signup | H41: - | I41: Shows 0 trips completed and 'no ratings yet' (not a broken/blank state) | J41: Run
A42: TRIP-001 | B42: Trip Creation (Driver) | C42: Create trip with all valid required fields | D42: High | E42: Functional | F42: Logged in as Driver | G42: 1. Go to Post a Trip 2. Fill origin, destination, date, time, seats, price, vehicle details 3. Submit | H42: Buckingham palace to London Eye, tomorrow 9:00, 4 seats, $300/seat | I42: Trip created successfully; appears in driver's trip list and passenger search | J42: Run
A43: TRIP-002 | B43: Trip Creation (Driver) | C43: Create trip with a required field missing | D43: High | E43: Negative | F43: Logged in as Driver, on Post a Trip | G43: 1. Leave destination blank 2. Submit | H43: Destination: (blank) | I43: Field-level validation error; trip not created | J43: Run
A44: TRIP-003 | B44: Trip Creation (Driver) | C44: Create trip with departure date in the past | D44: High | E44: Negative | F44: Logged in as Driver, on Post a Trip | G44: 1. Select a past date 2. Submit | H44: Date: yesterday | I44: Blocked with error per rule 'Cannot create trip in the past' | J44: Run
A45: TRIP-004 | B45: Trip Creation (Driver) | C45: Create trip for today with a time already passed | D45: Medium | E45: Edge Case | F45: Current time is after the selected departure time | G45: 1. Select today's date 2. Select a time earlier than current time 3. Submit | H45: Date: today, Time: 2 hours ago | I45: Blocked, treated as a past trip | J45: Run
A46: TRIP-005 | B46: Trip Creation (Driver) | C46: Create trip with identical origin and destination | D46: Medium | E46: Negative | F46: On Post a Trip | G46: 1. Enter the same city for origin and destination 2. Submit | H46: Origin: London Eye, Destination: London Eye | I46: Validation error preventing an illogical route (verify expected UX) | J46: Run
A47: TRIP-006 | B47: Trip Creation (Driver) | C47: Origin/destination autocomplete suggestions | D47: Medium | E47: UI | F47: On Post a Trip | G47: 1. Type partial city name in Origin field | H47: Lon' | I47: Matching city suggestions (e.g. London) appear in a dropdown | J47: Run
A48: TRIP-007 | B48: Trip Creation (Driver) | C48: Available seats - minimum boundary (1) | D48: Medium | E48: Edge Case | F48: On Post a Trip | G48: 1. Set available seats to 1 2. Submit | H48: Seats: 1 | I48: Trip created successfully with 1 seat | J48: Run
... A99: BOOK-011 | B99: Booking Flow | C99: Passenger cancels a Confirmed booking | D99: High | E99: Functional | F99: Passenger has a Confirmed booking | G99: 1. Passenger cancels the confirmed booking | H99: - | I99: Status set to Cancelled; cancellation/refund policy applied; seat released | J99: Run
A100: BOOK-012 | B100: Booking Flow | C100: Driver marks a trip/booking Completed | D100: High | E100: Functional | F100: Trip departure time has passed / trip took place | G100: 1. Driver marks trip as Completed | H100: - | I100: Booking status changes to Completed; payout triggered; rating becomes available | J100: Run | K100: no rating shown
A101: PAY-001 | B101: Payments | C101: Successful payment with valid card | D101: High | E101: Functional | F101: Passenger at payment step | G101: 1. Enter valid Stripe test card 2. Submit payment | H101: Stripe test card 4242 4242 4242 4242 | I101: Payment Intent succeeds; funds held (escrow-like); booking proceeds | J101: Run
A102: PAY-002 | B102: Payments | C102: Payment fails - card declined | D102: High | E102: Negative | F102: Passenger at payment step | G102: 1. Use a Stripe test card that triggers a decline 2. Submit | H102: Stripe decline test card | I102: Booking not confirmed; clear failure message; passenger can retry | J102: Run
A103: PAY-003 | B103: Payments | C103: Payment fails - insufficient funds | D103: Medium | E103: Negative | F103: Passenger at payment step | G103: 1. Use a test card simulating insufficient funds 2. Submit | H103: Stripe insufficient-funds test card | I103: Booking not confirmed; appropriate error message shown | J103: Run
A104: PAY-004 | B104: Payments | C104: Invalid/expired card details entered | D104: Medium | E104: Negative | F104: Passenger at payment step | G104: 1. Enter an expired card number 2. Submit | H104: Expired card | I104: Client-side validation error before submission to Stripe | J104: Run
A105: PAY-005 | B105: Payments | C105: Platform fee calculated correctly | D105: High | E105: Functional | F105: Booking payment processed | G105: 1. Complete a booking of known gross amount 2. Check platform fee recorded | H105: Gross: $1000, fee: 12% | I105: Platform fee = $120 (12% of $1000, matches configured %) | J105: Not Run
A106: PAY-006 | B106: Payments | C106: Net payout calculated correctly | D106: High | E106: Functional | F106: Booking payment processed | G106: 1. Check driver payout record for a completed trip | H106: Gross: $1000, fee: $100 | I106: Net payout = $900 (gross - fee) | J106: Not Run
A107: PAY-007 | B107: Payments | C107: Payout only released after trip Completed | D107: High | E107: Functional | F107: Booking is Confirmed but trip not yet marked Completed | G107: 1. Check driver payout status before trip completion | H107: - | I107: Payout is NOT released while status is Confirmed/Pending; only after Completed | J107: Not Run
A108: PAY-008 | B108: Payments | C108: Refund processed on eligible cancellation | D108: High | E108: Functional | F108: A Confirmed/Pending booking is cancelled within refund policy window | G108: 1. Cancel booking (driver rejects or passenger cancels early) 2. Check passenger payment status | H108: - | I108: Refund is issued and reflected as Refunded in payment status | J108: Not Run
A109: PAY-009 | B109: Payments | C109: Booking/payment record stores all required fields | D109: Medium | E109: Functional | F109: A booking payment exists | G109: 1. Inspect payment record (via admin or API) | H109: - | I109: Booking ID, gross amount, platform fee, net payout, and payment status all present and accurate | J109: Not Run
A110: PAY-010 | B110: Payments | C110: Payment status visible to passenger | D110: Medium | E110: UI | F110: A booking payment exists | G110: 1. Passenger views booking details | H110: - | I110: Correct status shown (e.g., Paid / Refunded / Failed) | J110: Not Run
A111: PAY-011 | B111: Payments | C111: Double-click on Pay button does not double-charge | D111: High | E111: Edge Case | F111: Passenger at payment step | G111: 1. Rapidly double-click the 'Pay' button | H111: - | I111: Only one charge is created; button disables after first click / idempotency enforced | J111: Not Run
...

Sheet Summary
A1: RideSeat MVP — Test Coverage Summary
A3: Module | B3: Total Cases | C3: High | D3: Medium | E3: Low | F3: % of Suite
A4: Authentication & Accounts | B4: =COUNTIF('Test Cases'!$B$2:$B$148,A4) | C4: =COUNTIFS('Test Cases'!$B$2:$B$148,A4,'Test Cases'!$D$2:$D$148,"High") | D4: =COUNTIFS('Test Cases'!$B$2:$B$148,A4,'Test Cases'!$D$2:$D$148,"Medium") | E4: =COUNTIFS('Test Cases'!$B$2:$B$148,A4,'Test Cases'!$D$2:$D$148,"Low") | F4: =B4/SUM($B$4:$B$14)
A5: User Profiles | B5: =COUNTIF('Test Cases'!$B$2:$B$148,A5) | C5: =COUNTIFS('Test Cases'!$B$2:$B$148,A5,'Test Cases'!$D$2:$D$148,"High") | D5: =COUNTIFS('Test Cases'!$B$2:$B$148,A5,'Test Cases'!$D$2:$D$148,"Medium") | E5: =COUNTIFS('Test Cases'!$B$2:$B$148,A5,'Test Cases'!$D$2:$D$148,"Low") | F5: =B5/SUM($B$4:$B$14)
A6: Trip Creation (Driver) | B6: =COUNTIF('Test Cases'!$B$2:$B$148,A6) | C6: =COUNTIFS('Test Cases'!$B$2:$B$148,A6,'Test Cases'!$D$2:$D$148,"High") | D6: =COUNTIFS('Test Cases'!$B$2:$B$148,A6,'Test Cases'!$D$2:$D$148,"Medium") | E6: =COUNTIFS('Test Cases'!$B$2:$B$148,A6,'Test Cases'!$D$2:$D$148,"Low") | F6: =B6/SUM($B$4:$B$14)
A7: Trip Discovery (Search) | B7: =COUNTIF('Test Cases'!$B$2:$B$148,A7) | C7: =COUNTIFS('Test Cases'!$B$2:$B$148,A7,'Test Cases'!$D$2:$D$148,"High") | D7: =COUNTIFS('Test Cases'!$B$2:$B$148,A7,'Test Cases'!$D$2:$D$148,"Medium") | E7: =COUNTIFS('Test Cases'!$B$2:$B$148,A7,'Test Cases'!$D$2:$D$148,"Low") | F7: =B7/SUM($B$4:$B$14)
A8: Trip Detail Page | B8: =COUNTIF('Test Cases'!$B$2:$B$148,A8) | C8: =COUNTIFS('Test Cases'!$B$2:$B$148,A8,'Test Cases'!$D$2:$D$148,"High") | D8: =COUNTIFS('Test Cases'!$B$2:$B$148,A8,'Test Cases'!$D$2:$D$148,"Medium") | E8: =COUNTIFS('Test Cases'!$B$2:$B$148,A8,'Test Cases'!$D$2:$D$148,"Low") | F8: =B8/SUM($B$4:$B$14)
A9: Booking Flow | B9: =COUNTIF('Test Cases'!$B$2:$B$148,A9) | C9: =COUNTIFS('Test Cases'!$B$2:$B$148,A9,'Test Cases'!$D$2:$D$148,"High") | D9: =COUNTIFS('Test Cases'!$B$2:$B$148,A9,'Test Cases'!$D$2:$D$148,"Medium") | E9: =COUNTIFS('Test Cases'!$B$2:$B$148,A9,'Test Cases'!$D$2:$D$148,"Low") | F9: =B9/SUM($B$4:$B$14)
A10: Payments | B10: =COUNTIF('Test Cases'!$B$2:$B$148,A10) | C10: =COUNTIFS('Test Cases'!$B$2:$B$148,A10,'Test Cases'!$D$2:$D$148,"High") | D10: =COUNTIFS('Test Cases'!$B$2:$B$148,A10,'Test Cases'!$D$2:$D$148,"Medium") | E10: =COUNTIFS('Test Cases'!$B$2:$B$148,A10,'Test Cases'!$D$2:$D$148,"Low") | F10: =B10/SUM($B$4:$B$14)
A11: Messaging | B11: =COUNTIF('Test Cases'!$B$2:$B$148,A11) | C11: =COUNTIFS('Test Cases'!$B$2:$B$148,A11,'Test Cases'!$D$2:$D$148,"High") | D11: =COUNTIFS('Test Cases'!$B$2:$B$148,A11,'Test Cases'!$D$2:$D$148,"Medium") | E11: =COUNTIFS('Test Cases'!$B$2:$B$148,A11,'Test Cases'!$D$2:$D$148,"Low") | F11: =B11/SUM($B$4:$B$14)
A12: Ratings & Reviews | B12: =COUNTIF('Test Cases'!$B$2:$B$148,A12) | C12: =COUNTIFS('Test Cases'!$B$2:$B$148,A12,'Test Cases'!$D$2:$D$148,"High") | D12: =COUNTIFS('Test Cases'!$B$2:$B$148,A12,'Test Cases'!$D$2:$D$148,"Medium") | E12: =COUNTIFS('Test Cases'!$B$2:$B$148,A12,'Test Cases'!$D$2:$D$148,"Low") | F12: =B12/SUM($B$4:$B$14)
A13: Admin | B13: =COUNTIF('Test Cases'!$B$2:$B$148,A13) | C13: =COUNTIFS('Test Cases'!$B$2:$B$148,A13,'Test Cases'!$D$2:$D$148,"High") | D13: =COUNTIFS('Test Cases'!$B$2:$B$148,A13,'Test Cases'!$D$2:$D$148,"Medium") | E13: =COUNTIFS('Test Cases'!$B$2:$B$148,A13,'Test Cases'!$D$2:$D$148,"Low") | F13: =B13/SUM($B$4:$B$14)
A14: Non-Functional / Cross-Cutting | B14: =COUNTIF('Test Cases'!$B$2:$B$148,A14) | C14: =COUNTIFS('Test Cases'!$B$2:$B$148,A14,'Test Cases'!$D$2:$D$148,"High") | D14: =COUNTIFS('Test Cases'!$B$2:$B$148,A14,'Test Cases'!$D$2:$D$148,"Medium") | E14: =COUNTIFS('Test Cases'!$B$2:$B$148,A14,'Test Cases'!$D$2:$D$148,"Low") | F14: =B14/SUM($B$4:$B$14)
A15: TOTAL | B15: =SUM(B4:B14) | C15: =SUM(C4:C14) | D15: =SUM(D4:D14) | E15: =SUM(E4:E14) | F15: =SUM(F4:F14)
A17: Note: PRD did not specify a booking-approval model explicitly (auto-confirm vs. driver-approval). Several test cases (BOOK-005, BOOK-008, BOOK-009) are written to be re-verified against whichever model is implemented. Figma UI could not be fetched automatically (robots-disallowed) — UI-specific assertions (exact copy, disabled-state styling) should be cross-checked manually against the designs.
